Workbook
Name GRADES: [1]Sheet1!$H$18:$I$25
Name GRADES2: [1]Sheet1!#REF!
Name GRADES2: [1]Sheet1!#REF!
Name Order_Month: [1]Orders!#REF!
Name Order_Month: [1]Orders!#REF!
Name Order_No: [1]Orders!$A$6:$A$1044
Name Order_Priority: [1]Orders!$J$6:$J$1044
Name Ship_Date: [1]Orders!$O$6:$O$1044
Name Ship_Time: [1]Orders!#REF!
Name Ship_Time: [1]Orders!#REF!
Name Slicer_Branch: #N/A
Name Slicer_Category: #N/A
Name Slicer_Class: #N/A
Name Slicer_Class1: #N/A
Name Slicer_G._Segment: #N/A
Name Slicer_Product: #N/A
Name Slicer_Region: #N/A

Sheet Info
A1: Based on the given data Find
A4: 1 | B4: Use Data-1 Sheet, Change data to tabled data & Name it with your Name & Tack & Gov
A5: 2 | B5: ToTal sales
A6: 3 | B6: Total Profit
A7: 4 | B7: No of Quentity
A8: 5 | B8: Profit after Discount
A9: 6 | B9: Second High Sales
A10: 7 | B10: Fourth Low Sales
A11: 8 | B11: Max Profit
A12: 9 | B12: Total High Sales>3000
A13: 10 | B13: No of High Sales
A14: 11 | B14: IF New Price = 150 Find New Sales
A15: 12 | B15: Give Those classes to New Sales as Following
C16: A | D16: 2000 | E16: D | F16: 100
C17: B | D17: 1000 | E17: E | F17: less than 100
C18: C | D18: 500
A19: 13 | B19: Average of Top 3 Profit Value
A20: 14 | B20: Max new sales
A21: 15 | B21: Min new sales
A22: 16 | B22: average new sales
A23: 17 | B23: Find Total New sales If State = California
A24: 18 | B24: Find Average New Sales If state = Texas
A25: 19 | B25: Highlight All Sub Category = Phones ( using Custom Format)
A26: 20 | B26: Highlight all Negative Values in Profit
A27: 21 | B27: use code sheet to assign each code to relative data in Category Column
A28: 22 | B28: use spark line (Columns) to find change between sales & new sales
A29: 23 | B29: Based on Sales sheet, use Piviot Table to Find:
B30: ● | C30: Avgerage Profit by region
B31: ● | C31: sum of profit by region and segment
B32: ● | C32: Calculate discount by 5% on profit
B33: ● | C33: Count profit by category and sub category & segment
B34: ● | C34: insert slicer for each piviot
B35: ● | C35: insert piviot chart for all piviots and link them together
A36: 24 | B36: Use the data in sales sheet to analyze and convert all necessary data to chart from your own perspective
A37: 25 | B37: Create your Detailed interactive dashboard Based on analyzed data in NO (24)
A39: ** all answers in one book with the folowing Info:
A40: Delivery Period: | D40: 2 Days MAX
A41: Satuden Name: | D41: Mahmoud Elbaal
A42: Gov:
A43: Group:
...

Sheet Data-1
K1: 150
A2: Row ID | B2: Ship Mode | C2: Segment | D2: City | E2: State | F2: Region | G2: Category | H2: Code | I2: Sub-Category | J2: Product Name | K2: Sales | L2: New Sales | M2: Price | N2: Quantity | O2: Discount | P2: Profit | Q2: profit after discout | R2: Class | S2: Change between Sales & New Sales
A3: 1 | B3: Second Class | C3: Consumer | D3: Henderson | E3: Kentucky | F3: South | G3: Furniture | H3: =VLOOKUP(Product[[#This Row],[Category]],Code!$C$2:$D$5,2,0) -> F-101 | I3: Bookcases | J3: Bush Somerset Collection Bookcase | K3: 261.96 | L3: =$K$1*Product[[#This Row],[Quantity]] -> 300 | M3: =Product[[#This Row],[Sales]]/Product[[#This Row],[Quantity]] -> 130.98 | N3: 2 | O3: 0 | P3: 41.9136 | Q3: =Product[[#This Row],[Profit]]-Product[[#This Row],[Discount]] -> 41.9136 | R3: {=_xlfn.IFS(Product[[#This Row],[New Sales]]>=2000,"A",Product[[#This Row],[New Sales]]>=1000,"B",Product[[#This Row],[New Sales]]>=500,"C",Product[[#This Row],[New Sales]]>=100,"D",Product[[#This Row],[New Sales]]<100,"E")} -> D
A4: 2 | B4: Second Class | C4: Consumer | D4: Henderson | E4: Kentucky | F4: South | G4: Furniture | H4: =VLOOKUP(Product[[#This Row],[Category]],Code!$C$2:$D$5,2,0) -> F-101 | I4: Chairs | J4: Hon Deluxe Fabric Upholstered Stacking Chairs, Rounded Back | K4: 731.94 | L4: =$K$1*Product[[#This Row],[Quantity]] -> 450 | M4: =Product[[#This Row],[Sales]]/Product[[#This Row],[Quantity]] -> 243.98 | N4: 3 | O4: 0 | P4: 219.582 | Q4: =Product[[#This Row],[Profit]]-Product[[#This Row],[Discount]] -> 219.582 | R4: {=_xlfn.IFS(Product[[#This Row],[New Sales]]>=2000,"A",Product[[#This Row],[New Sales]]>=1000,"B",Product[[#This Row],[New Sales]]>=500,"C",Product[[#This Row],[New Sales]]>=100,"D",Product[[#This Row],[New Sales]]<100,"E")} -> D
A5: 3 | B5: Second Class | C5: Corporate | D5: Los Angeles | E5: California | F5: West | G5: Office Supplies | H5: =VLOOKUP(Product[[#This Row],[Category]],Code!$C$2:$D$5,2,0) -> O-102 | I5: Labels | J5: Self-Adhesive Address Labels for Typewriters by Universal | L5: =$K$1*Product[[#This Row],[Quantity]] -> 300 | M5: =Product[[#This Row],[Sales]]/Product[[#This Row],[Quantity]] -> 0 | N5: 2 | O5: 0 | P5: 6.8714 | Q5: =Product[[#This Row],[Profit]]-Product[[#This Row],[Discount]] -> 6.8714 | R5: {=_xlfn.IFS(Product[[#This Row],[New Sales]]>=2000,"A",Product[[#This Row],[New Sales]]>=1000,"B",Product[[#This Row],[New Sales]]>=500,"C",Product[[#This Row],[New Sales]]>=100,"D",Product[[#This Row],[New Sales]]<100,"E")} -> D
A6: 4 | B6: Standard Class | C6: Consumer | D6: Fort Lauderdale | E6: Florida | F6: South | G6: Furniture | H6: =VLOOKUP(Product[[#This Row],[Category]],Code!$C$2:$D$5,2,0) -> F-101 | I6: Tables | J6: Bretford CR4500 Series Slim Rectangular Table | K6: 957.5775 | L6: =$K$1*Product[[#This Row],[Quantity]] -> 750 | M6: =Product[[#This Row],[Sales]]/Product[[#This Row],[Quantity]] -> 191.5155 | N6: 5 | O6: 0.45 | P6: -383.031 | Q6: =Product[[#This Row],[Profit]]-Product[[#This Row],[Discount]] -> -383.481 | R6: {=_xlfn.IFS(Product[[#This Row],[New Sales]]>=2000,"A",Product[[#This Row],[New Sales]]>=1000,"B",Product[[#This Row],[New Sales]]>=500,"C",Product[[#This Row],[New Sales]]>=100,"D",Product[[#This Row],[New Sales]]<100,"E")} -> C
A7: 5 | B7: Standard Class | C7: Consumer | D7: Fort Lauderdale | E7: Florida | F7: South | G7: Office Supplies | H7: =VLOOKUP(Product[[#This Row],[Category]],Code!$C$2:$D$5,2,0) -> O-102 | I7: Storage | J7: Eldon Fold 'N Roll Cart System | K7: 22.368 | L7: =$K$1*Product[[#This Row],[Quantity]] -> 300 | M7: =Product[[#This Row],[Sales]]/Product[[#This Row],[Quantity]] -> 11.184 | N7: 2 | O7: 0.2 | P7: 2.5164 | Q7: =Product[[#This Row],[Profit]]-Product[[#This Row],[Discount]] -> 2.3164 | R7: {=_xlfn.IFS(Product[[#This Row],[New Sales]]>=2000,"A",Product[[#This Row],[New Sales]]>=1000,"B",Product[[#This Row],[New Sales]]>=500,"C",Product[[#This Row],[New Sales]]>=100,"D",Product[[#This Row],[New Sales]]<100,"E")} -> D
A8: 6 | B8: Standard Class | C8: Consumer | D8: Los Angeles | E8: California | F8: West | G8: Furniture | H8: =VLOOKUP(Product[[#This Row],[Category]],Code!$C$2:$D$5,2,0) -> F-101 | I8: Furnishings | J8: Eldon Expressions Wood and Plastic Desk Accessories, Cherry Wood | K8: 48.86 | L8: =$K$1*Product[[#This Row],[Quantity]] -> 1050 | M8: =Product[[#This Row],[Sales]]/Product[[#This Row],[Quantity]] -> 6.98 | N8: 7 | O8: 0 | P8: 14.1694 | Q8: =Product[[#This Row],[Profit]]-Product[[#This Row],[Discount]] -> 14.1694 | R8: {=_xlfn.IFS(Product[[#This Row],[New Sales]]>=2000,"A",Product[[#This Row],[New Sales]]>=1000,"B",Product[[#This Row],[New Sales]]>=500,"C",Product[[#This Row],[New Sales]]>=100,"D",Product[[#This Row],[New Sales]]<100,"E")} -> B
A9: 7 | B9: Standard Class | C9: Consumer | D9: Los Angeles | E9: California | F9: West | G9: Office Supplies | H9: =VLOOKUP(Product[[#This Row],[Category]],Code!$C$2:$D$5,2,0) -> O-102 | I9: Art | J9: Newell 322 | K9: 7.28 | L9: =$K$1*Product[[#This Row],[Quantity]] -> 600 | M9: =Product[[#This Row],[Sales]]/Product[[#This Row],[Quantity]] -> 1.82 | N9: 4 | O9: 0 | P9: 1.9656 | Q9: =Product[[#This Row],[Profit]]-Product[[#This Row],[Discount]] -> 1.9656 | R9: {=_xlfn.IFS(Product[[#This Row],[New Sales]]>=2000,"A",Product[[#This Row],[New Sales]]>=1000,"B",Product[[#This Row],[New Sales]]>=500,"C",Product[[#This Row],[New Sales]]>=100,"D",Product[[#This Row],[New Sales]]<100,"E")} -> C
A10: 8 | B10: Standard Class | C10: Consumer | D10: Los Angeles | E10: California | F10: West | G10: Technology | H10: =VLOOKUP(Product[[#This Row],[Category]],Code!$C$2:$D$5,2,0) -> T-103 | I10: Phones | J10: Mitel 5320 IP Phone VoIP phone | K10: 907.152 | L10: =$K$1*Product[[#This Row],[Quantity]] -> 900 | M10: =Product[[#This Row],[Sales]]/Product[[#This Row],[Quantity]] -> 151.192 | N10: 6 | O10: 0.2 | P10: 90.7152 | Q10: =Product[[#This Row],[Profit]]-Product[[#This Row],[Discount]] -> 90.5152 | R10: {=_xlfn.IFS(Product[[#This Row],[New Sales]]>=2000,"A",Product[[#This Row],[New Sales]]>=1000,"B",Product[[#This Row],[New Sales]]>=500,"C",Product[[#This Row],[New Sales]]>=100,"D",Product[[#This Row],[New Sales]]<100,"E")} -> C
A11: 9 | B11: Standard Class | C11: Consumer | D11: Los Angeles | E11: California | F11: West | G11: Office Supplies | H11: =VLOOKUP(Product[[#This Row],[Category]],Code!$C$2:$D$5,2,0) -> O-102 | I11: Binders | J11: DXL Angle-View Binders with Locking Rings by Samsill | K11: 18.504 | L11: =$K$1*Product[[#This Row],[Quantity]] -> 450 | M11: =Product[[#This Row],[Sales]]/Product[[#This Row],[Quantity]] -> 6.168 | N11: 3 | O11: 0.2 | P11: 5.7825 | Q11: =Product[[#This Row],[Profit]]-Product[[#This Row],[Discount]] -> 5.5825 | R11: {=_xlfn.IFS(Product[[#This Row],[New Sales]]>=2000,"A",Product[[#This Row],[New Sales]]>=1000,"B",Product[[#This Row],[New Sales]]>=500,"C",Product[[#This Row],[New Sales]]>=100,"D",Product[[#This Row],[New Sales]]<100,"E")} -> D
A12: 10 | B12: Standard Class | C12: Consumer | D12: Los Angeles | E12: California | F12: West | G12: Office Supplies | H12: =VLOOKUP(Product[[#This Row],[Category]],Code!$C$2:$D$5,2,0) -> O-102 | I12: Appliances | J12: Belkin F5C206VTEL 6 Outlet Surge | K12: 114.9 | L12: =$K$1*Product[[#This Row],[Quantity]] -> 750 | M12: =Product[[#This Row],[Sales]]/Product[[#This Row],[Quantity]] -> 22.98 | N12: 5 | O12: 0 | P12: 34.47 | Q12: =Product[[#This Row],[Profit]]-Product[[#This Row],[Discount]] -> 34.47 | R12: {=_xlfn.IFS(Product[[#This Row],[New Sales]]>=2000,"A",Product[[#This Row],[New Sales]]>=1000,"B",Product[[#This Row],[New Sales]]>=500,"C",Product[[#This Row],[New Sales]]>=100,"D",Product[[#This Row],[New Sales]]<100,"E")} -> C
A13: 11 | B13: Standard Class | C13: Consumer | D13: Los Angeles | E13: California | F13: West | G13: Furniture | H13: =VLOOKUP(Product[[#This Row],[Category]],Code!$C$2:$D$5,2,0) -> F-101 | I13: Tables | J13: Chromcraft Rectangular Conference Tables | K13: 1706.184 | L13: =$K$1*Product[[#This Row],[Quantity]] -> 1350 | M13: =Product[[#This Row],[Sales]]/Product[[#This Row],[Quantity]] -> 189.576 | N13: 9 | O13: 0.2 | P13: 85.3092 | Q13: =Product[[#This Row],[Profit]]-Product[[#This Row],[Discount]] -> 85.1092 | R13: {=_xlfn.IFS(Product[[#This Row],[New Sales]]>=2000,"A",Product[[#This Row],[New Sales]]>=1000,"B",Product[[#This Row],[New Sales]]>=500,"C",Product[[#This Row],[New Sales]]>=100,"D",Product[[#This Row],[New Sales]]<100,"E")} -> B
A14: 12 | B14: Standard Class | C14: Consumer | D14: Los Angeles | E14: California | F14: West | G14: Technology | H14: =VLOOKUP(Product[[#This Row],[Category]],Code!$C$2:$D$5,2,0) -> T-103 | I14: Phones | J14: Konftel 250 Conference phone - Charcoal black | K14: 911.424 | L14: =$K$1*Product[[#This Row],[Quantity]] -> 600 | M14: =Product[[#This Row],[Sales]]/Product[[#This Row],[Quantity]] -> 227.856 | N14: 4 | O14: 0.2 | P14: 68.3568 | Q14: =Product[[#This Row],[Profit]]-Product[[#This Row],[Discount]] -> 68.1568 | R14: {=_xlfn.IFS(Product[[#This Row],[New Sales]]>=2000,"A",Product[[#This Row],[New Sales]]>=1000,"B",Product[[#This Row],[New Sales]]>=500,"C",Product[[#This Row],[New Sales]]>=100,"D",Product[[#This Row],[New Sales]]<100,"E")} -> C
A15: 13 | B15: Standard Class | C15: Consumer | D15: Concord | E15: North Carolina | F15: South | G15: Office Supplies | H15: =VLOOKUP(Product[[#This Row],[Category]],Code!$C$2:$D$5,2,0) -> O-102 | I15: Paper | J15: Xerox 1967 | K15: 15.552 | L15: =$K$1*Product[[#This Row],[Quantity]] -> 450 | M15: =Product[[#This Row],[Sales]]/Product[[#This Row],[Quantity]] -> 5.184 | N15: 3 | O15: 0.2 | P15: 5.4432 | Q15: =Product[[#This Row],[Profit]]-Product[[#This Row],[Discount]] -> 5.2432 | R15: {=_xlfn.IFS(Product[[#This Row],[New Sales]]>=2000,"A",Product[[#This Row],[New Sales]]>=1000,"B",Product[[#This Row],[New Sales]]>=500,"C",Product[[#This Row],[New Sales]]>=100,"D",Product[[#This Row],[New Sales]]<100,"E")} -> D
A16: 14 | B16: Standard Class | C16: Consumer | D16: Seattle | E16: Washington | F16: West | G16: Office Supplies | H16: =VLOOKUP(Product[[#This Row],[Category]],Code!$C$2:$D$5,2,0) -> O-102 | I16: Binders | J16: Fellowes PB200 Plastic Comb Binding Machine | K16: 407.976 | L16: =$K$1*Product[[#This Row],[Quantity]] -> 450 | M16: =Product[[#This Row],[Sales]]/Product[[#This Row],[Quantity]] -> 135.992 | N16: 3 | O16: 0.2 | P16: 132.5922 | Q16: =Product[[#This Row],[Profit]]-Product[[#This Row],[Discount]] -> 132.3922 | R16: {=_xlfn.IFS(Product[[#This Row],[New Sales]]>=2000,"A",Product[[#This Row],[New Sales]]>=1000,"B",Product[[#This Row],[New Sales]]>=500,"C",Product[[#This Row],[New Sales]]>=100,"D",Product[[#This Row],[New Sales]]<100,"E")} -> D
A17: 15 | B17: Standard Class | C17: Home Office | D17: Fort Worth | E17: Texas | F17: Central | G17: Office Supplies | H17: =VLOOKUP(Product[[#This Row],[Category]],Code!$C$2:$D$5,2,0) -> O-102 | I17: Appliances | J17: Holmes Replacement Filter for HEPA Air Cleaner, Very Large Room, HEPA Filter | K17: 68.81 | L17: =$K$1*Product[[#This Row],[Quantity]] -> 750 | M17: =Product[[#This Row],[Sales]]/Product[[#This Row],[Quantity]] -> 13.762 | N17: 5 | O17: 0.8 | P17: -123.858 | Q17: =Product[[#This Row],[Profit]]-Product[[#This Row],[Discount]] -> -124.658 | R17: {=_xlfn.IFS(Product[[#This Row],[New Sales]]>=2000,"A",Product[[#This Row],[New Sales]]>=1000,"B",Product[[#This Row],[New Sales]]>=500,"C",Product[[#This Row],[New Sales]]>=100,"D",Product[[#This Row],[New Sales]]<100,"E")} -> C
... A2001: 1999 | B2001: First Class | C2001: Corporate | D2001: Chesapeake | E2001: Virginia | F2001: South | G2001: Technology | H2001: =VLOOKUP(Product[[#This Row],[Category]],Code!$C$2:$D$5,2,0) -> T-103 | I2001: Phones | J2001: Aastra 57i VoIP phone | K2001: 161.61 | L2001: =$K$1*Product[[#This Row],[Quantity]] -> 150 | M2001: =Product[[#This Row],[Sales]]/Product[[#This Row],[Quantity]] -> 161.61 | N2001: 1 | O2001: 0 | P2001: 42.0186 | Q2001: =Product[[#This Row],[Profit]]-Product[[#This Row],[Discount]] -> 42.0186 | R2001: {=_xlfn.IFS(Product[[#This Row],[New Sales]]>=2000,"A",Product[[#This Row],[New Sales]]>=1000,"B",Product[[#This Row],[New Sales]]>=500,"C",Product[[#This Row],[New Sales]]>=100,"D",Product[[#This Row],[New Sales]]<100,"E")} -> D
B2005: ToTal sales | D2005: =SUM(Product[Sales]) -> 457738.49
B2006: Total Profit | D2006: =SUM(Product[Profit]) -> 43208.147
B2007: No of Quantity | D2007: =COUNT(Product[Quantity]) -> 1999
B2008: Profit after Discount | D2008: =SUM(Product[profit after discout]) -> 42888.467
B2009: Second High Sales | D2009: =LARGE(Product[Sales],2) -> 7999.98
B2010: Fourth Low Sales | D2010: =SMALL(Product[Sales],4) -> 1.188
B2011: Max Profit | D2011: =MAX(Product[Profit]) -> 3177.475
B2012: Total High Sales>3000 | D2012: =SUMIF(Product[Sales],">3000") -> 62777.238
B2013: No of High Sales | D2013: =COUNTIF(Product[Sales],">3000") -> 14
B2014: Average of Top 3 Profit Value | D2014: {=AVERAGE(LARGE(Product[Profit],{1,2,3}))} -> 2524.8102
B2015: Max New Sales | D2015: =MAX(Product[New Sales]) -> 2100
B2016: Min New Sales | D2016: =MIN(Product[New Sales]) -> 150
B2017: AVG New Sales | D2017: =AVERAGE(Product[New Sales]) -> 568.10905
B2018: Find Total New sales If State = California | D2018: =SUMIFS(Product[New Sales],Product[State],"California") -> 213300
B2019: Find Average New Sales If state = Texas | D2019: =AVERAGEIFS(Product[New Sales],Product[State],"Texas") -> 578.57143

Sheet Code
C2: Category | D2: Code
C3: Furniture | D3: F-101
C4: Office Supplies | D4: O-102
C5: Technology | D5: T-103

Sheet Pivot table (data-1)
A3: Row Labels | B3: Average of Profit | E3: Row Labels | F3: Count of Profit
A4: Central | B4: 6.331251 | E4: Consumer | F4: 1070
A5: East | B5: 17.559164 | E5: Corporate | F5: 586
A6: South | B6: 31.76299 | E6: Home Office | F6: 343
A7: West | B7: 32.657965 | E7: Grand Total | F7: 1999
A8: Grand Total | B8: 21.614881
A11: Row Labels | B11: Sum of Profit
A12: Central | B12: 2994.6817
A13: East | B13: 10886.682
A14: South | B14: 9274.793
A15: West | B15: 20051.99
A16: Grand Total | B16: 43208.147
A19: Row Labels | B19: Sum of Profit | C19: Sum of Discount
A20: Central | B20: 2994.6817 | C20: 106.18
A21: East | B21: 10886.682 | C21: 95.6
A22: South | B22: 9274.793 | C22: 43.7
A23: West | B23: 20051.99 | C23: 74.2
A24: Grand Total | B24: 43208.147 | C24: 319.68

Sheet Pivot chart (data-1)

Sheet Sales
N1: 0.05
A2: Date | B2: Branch | C2: G. Segment | D2: Product | E2: Class | F2: Quantity | G2: Unit Cost | H2: Unit Price | I2: COGS | J2: Sales | K2: Revenue | L2: Cost | M2: Profit | N2: Discount | O2: New Profit
A3: 40909 | B3: Marasa Matrouh | C3: Alexandria | D3: Nokia Lumia - 4G | E3: Smartphones | F3: 8 | G3: 2034 | H3: 2160 | I3: 16272 | J3: 40053 | K3: =Sales[[#This Row],[Unit Price]]*Sales[[#This Row],[Quantity]] -> 17280 | L3: =Sales[[#This Row],[Unit Cost]]*Sales[[#This Row],[Quantity]] -> 16272 | M3: =Sales[[#This Row],[Revenue]]-Sales[[#This Row],[Cost]] -> 1008 | N3: =Sales[[#This Row],[Profit]]*$N$1 -> 50.4 | O3: =Sales[[#This Row],[Profit]]-Sales[[#This Row],[Discount ]] -> 957.6
A4: 40909 | B4: Alex | C4: Alexandria | D4: Samsung Galaxy Note 10.1 | E4: Tablets | F4: 21 | G4: 3582 | H4: 3870 | I4: 75222 | J4: 81270 | K4: =Sales[[#This Row],[Unit Price]]*Sales[[#This Row],[Quantity]] -> 81270 | L4: =Sales[[#This Row],[Unit Cost]]*Sales[[#This Row],[Quantity]] -> 75222 | M4: =Sales[[#This Row],[Revenue]]-Sales[[#This Row],[Cost]] -> 6048 | N4: =Sales[[#This Row],[Profit]]*$N$1 -> 302.4 | O4: =Sales[[#This Row],[Profit]]-Sales[[#This Row],[Discount ]] -> 5745.6
A5: 40909 | B5: Zagazig | C5: Delta | D5: Samsung Galaxy Note3 (32GB) - 4G | E5: Smartphones | F5: 16 | G5: 3978 | H5: 4230 | I5: 63648 | J5: 67680 | K5: =Sales[[#This Row],[Unit Price]]*Sales[[#This Row],[Quantity]] -> 67680 | L5: =Sales[[#This Row],[Unit Cost]]*Sales[[#This Row],[Quantity]] -> 63648 | M5: =Sales[[#This Row],[Revenue]]-Sales[[#This Row],[Cost]] -> 4032 | N5: =Sales[[#This Row],[Profit]]*$N$1 -> 201.6 | O5: =Sales[[#This Row],[Profit]]-Sales[[#This Row],[Discount ]] -> 3830.4
A6: 40909 | B6: Mansoura | C6: Delta | D6: Samsung Galaxy S3 (16GB) - 3G | E6: Smartphones | F6: 23 | G6: 2196 | H6: 2340 | I6: 50508 | J6: 53820 | K6: =Sales[[#This Row],[Unit Price]]*Sales[[#This Row],[Quantity]] -> 53820 | L6: =Sales[[#This Row],[Unit Cost]]*Sales[[#This Row],[Quantity]] -> 50508 | M6: =Sales[[#This Row],[Revenue]]-Sales[[#This Row],[Cost]] -> 3312 | N6: =Sales[[#This Row],[Profit]]*$N$1 -> 165.6 | O6: =Sales[[#This Row],[Profit]]-Sales[[#This Row],[Discount ]] -> 3146.4
A7: 40910 | B7: Ismailia | C7: Canal | D7: Samsung Galaxy Note3 (32GB) - 4G | E7: Smartphones | F7: 22 | G7: 3978 | H7: 4230 | I7: 87516 | J7: 93060 | K7: =Sales[[#This Row],[Unit Price]]*Sales[[#This Row],[Quantity]] -> 93060 | L7: =Sales[[#This Row],[Unit Cost]]*Sales[[#This Row],[Quantity]] -> 87516 | M7: =Sales[[#This Row],[Revenue]]-Sales[[#This Row],[Cost]] -> 5544 | N7: =Sales[[#This Row],[Profit]]*$N$1 -> 277.2 | O7: =Sales[[#This Row],[Profit]]-Sales[[#This Row],[Discount ]] -> 5266.8
A8: 40910 | B8: Minia | C8: Upper Egypt | D8: Samsung Galaxy Note3 (32GB) - 4G | E8: Smartphones | F8: 13 | G8: 3978 | H8: 4230 | I8: 51714 | J8: 54990 | K8: =Sales[[#This Row],[Unit Price]]*Sales[[#This Row],[Quantity]] -> 54990 | L8: =Sales[[#This Row],[Unit Cost]]*Sales[[#This Row],[Quantity]] -> 51714 | M8: =Sales[[#This Row],[Revenue]]-Sales[[#This Row],[Cost]] -> 3276 | N8: =Sales[[#This Row],[Profit]]*$N$1 -> 163.8 | O8: =Sales[[#This Row],[Profit]]-Sales[[#This Row],[Discount ]] -> 3112.2
A9: 40910 | B9: Alex | C9: Alexandria | D9: Samsung Galaxy S4 (16GB) - 4G | E9: Smartphones | F9: 27 | G9: 3042 | H9: 3240 | I9: 82134 | J9: 87480 | K9: =Sales[[#This Row],[Unit Price]]*Sales[[#This Row],[Quantity]] -> 87480 | L9: =Sales[[#This Row],[Unit Cost]]*Sales[[#This Row],[Quantity]] -> 82134 | M9: =Sales[[#This Row],[Revenue]]-Sales[[#This Row],[Cost]] -> 5346 | N9: =Sales[[#This Row],[Profit]]*$N$1 -> 267.3 | O9: =Sales[[#This Row],[Profit]]-Sales[[#This Row],[Discount ]] -> 5078.7
A10: 40910 | B10: Portsaied | C10: Canal | D10: Samsung Galaxy Note3 (32GB) - 4G | E10: Smartphones | F10: 27 | G10: 3978 | H10: 4230 | I10: 107406 | J10: 114210 | K10: =Sales[[#This Row],[Unit Price]]*Sales[[#This Row],[Quantity]] -> 114210 | L10: =Sales[[#This Row],[Unit Cost]]*Sales[[#This Row],[Quantity]] -> 107406 | M10: =Sales[[#This Row],[Revenue]]-Sales[[#This Row],[Cost]] -> 6804 | N10: =Sales[[#This Row],[Profit]]*$N$1 -> 340.2 | O10: =Sales[[#This Row],[Profit]]-Sales[[#This Row],[Discount ]] -> 6463.8
A11: 40912 | B11: Marasa Matrouh | C11: Alexandria | D11: Samsung Galaxy Note3 (32GB) - 4G | E11: Smartphones | F11: 27 | G11: 3978 | H11: 4230 | I11: 107406 | J11: 114210 | K11: =Sales[[#This Row],[Unit Price]]*Sales[[#This Row],[Quantity]] -> 114210 | L11: =Sales[[#This Row],[Unit Cost]]*Sales[[#This Row],[Quantity]] -> 107406 | M11: =Sales[[#This Row],[Revenue]]-Sales[[#This Row],[Cost]] -> 6804 | N11: =Sales[[#This Row],[Profit]]*$N$1 -> 340.2 | O11: =Sales[[#This Row],[Profit]]-Sales[[#This Row],[Discount ]] -> 6463.8
A12: 40913 | B12: Minia | C12: Upper Egypt | D12: iPhone 5S (64GB) | E12: Smartphones | F12: 27 | G12: 5832 | H12: 6210 | I12: 157464 | J12: 167670 | K12: =Sales[[#This Row],[Unit Price]]*Sales[[#This Row],[Quantity]] -> 167670 | L12: =Sales[[#This Row],[Unit Cost]]*Sales[[#This Row],[Quantity]] -> 157464 | M12: =Sales[[#This Row],[Revenue]]-Sales[[#This Row],[Cost]] -> 10206 | N12: =Sales[[#This Row],[Profit]]*$N$1 -> 510.3 | O12: =Sales[[#This Row],[Profit]]-Sales[[#This Row],[Discount ]] -> 9695.7
A13: 40913 | B13: Cairo | C13: G. Cairo | D13: Samsung Galaxy S3 (16GB) - 3G | E13: Smartphones | F13: 27 | G13: 2196 | H13: 2340 | I13: 59292 | J13: 63180 | K13: =Sales[[#This Row],[Unit Price]]*Sales[[#This Row],[Quantity]] -> 63180 | L13: =Sales[[#This Row],[Unit Cost]]*Sales[[#This Row],[Quantity]] -> 59292 | M13: =Sales[[#This Row],[Revenue]]-Sales[[#This Row],[Cost]] -> 3888 | N13: =Sales[[#This Row],[Profit]]*$N$1 -> 194.4 | O13: =Sales[[#This Row],[Profit]]-Sales[[#This Row],[Discount ]] -> 3693.6
A14: 40913 | B14: Giza | C14: G. Cairo | D14: iPhone 5C (16GB) | E14: Smartphones | F14: 27 | G14: 3546 | H14: 3780 | I14: 95742 | J14: 102060 | K14: =Sales[[#This Row],[Unit Price]]*Sales[[#This Row],[Quantity]] -> 102060 | L14: =Sales[[#This Row],[Unit Cost]]*Sales[[#This Row],[Quantity]] -> 95742 | M14: =Sales[[#This Row],[Revenue]]-Sales[[#This Row],[Cost]] -> 6318 | N14: =Sales[[#This Row],[Profit]]*$N$1 -> 315.9 | O14: =Sales[[#This Row],[Profit]]-Sales[[#This Row],[Discount ]] -> 6002.1
... A3002: 41912 | B3002: Portsaied | C3002: Canal | D3002: iPhone 5C (32GB) | E3002: Smartphones | F3002: 6 | G3002: 3546 | H3002: 3780 | I3002: 3978 | J3002: 4230 | K3002: =Sales[[#This Row],[Unit Price]]*Sales[[#This Row],[Quantity]] -> 22680 | L3002: =Sales[[#This Row],[Unit Cost]]*Sales[[#This Row],[Quantity]] -> 21276 | M3002: =Sales[[#This Row],[Revenue]]-Sales[[#This Row],[Cost]] -> 1404 | N3002: =Sales[[#This Row],[Profit]]*$N$1 -> 70.2 | O3002: =Sales[[#This Row],[Profit]]-Sales[[#This Row],[Discount ]] -> 1333.8

Sheet Pivot table (Sales)
A3: Row Labels | B3: Average of Profit | D3: Row Labels | E3: Sum of Profit | G3: Row Labels | H3: Count of Profit | J3: Row Labels | K3: Sum of New Profit
A4: Alex | B4: 3744 | D4: Alex | E4: 1123200 | G4: Alexandria | H4: 601 | J4: HTC One - (32GB) - 4G | K4: 651561.3
A5: Aswan | B5: 3571.9278 | D5: Aswan | E5: 989424 | G5: Canal | H5: 607 | J5: HTC ONE (32GB) Dual Sim - 3G | K5: 582545.7
A6: Cairo | B6: 3499.0067 | D6: Cairo | E6: 1042704 | G6: Delta | H6: 607 | J6: iPhone 5C (16GB) | K6: 554501.7
A7: Giza | B7: 3750.5619 | D7: Giza | E7: 1121418 | G7: G. Cairo | H7: 597 | J7: iPhone 5C (32GB) | K7: 593335.8
A8: Ismailia | B8: 3777.8601 | D8: Ismailia | E8: 1080468 | G8: Upper Egypt | H8: 588 | J8: iPhone 5S (16GB) | K8: 555903.9
A9: Mansoura | B9: 3578.82 | D9: Mansoura | E9: 1073646 | G9: Grand Total | H9: 3000 | J9: iPhone 5S (32GB) | K9: 654759
A10: Marasa Matrouh | B10: 3595.515 | D10: Marasa Matrouh | E10: 1082250 | J10: iPhone 5S (64GB) | K10: 598927.5
A11: Minia | B11: 3621.4727 | D11: Minia | E11: 1126278 | J11: Microsoft Surface Pro 2 | K11: 580818.6
A12: Portsaied | B12: 3672.2243 | D12: Portsaied | E12: 1178784 | J12: Nokia Lumia - 4G | K12: 662265.9
A13: Zagazig | B13: 3581.5309 | D13: Zagazig | E13: 1099530 | J13: Samsung Galaxy Note 10.1 | K13: 680220.9
A14: Grand Total | B14: 3639.234 | D14: Grand Total | E14: 10917702 | J14: Samsung Galaxy Note3 (32GB) - 3G | K14: 663103.8
J15: Samsung Galaxy Note3 (32GB) - 4G | K15: 621687.6
J16: Samsung Galaxy S3 (16GB) - 3G | K16: 564642
J17: Samsung Galaxy S4 (16GB) - 3G | K17: 676236.6
J18: Samsung Galaxy S4 (16GB) - 4G | K18: 592002
J19: Samsung Galaxy S4 Zoom - 3G | K19: 530681.4
J20: Sony Xperia Z | K20: 608623.2
J21: Grand Total | K21: 10371817

Sheet DashBoard
